<?xml version='1.0' encoding='utf-8'?>
<mujoco model="right_faive_modular">
    <compiler angle="radian" />
    <compiler angle="radian" />
    <option />
    <default>
        
        
        <geom rgba="1 1 1 1" type="mesh" density="662" friction="1 0.005 0.001" condim="3" margin="0.0005" contype="1" conaffinity="1" />
        
        
        <joint type="hinge" limited="true" damping="0.05" armature="0.001" margin="0.01" frictionloss="0.001" />
        
        <position ctrllimited="true" forcelimited="true" forcerange="-1 1" kp="2." />
        
        <tendon limited="true" range="-0.001 0.001" />
    </default>
    <asset>
        
        <mesh name="base" file="mesh/base.stl" scale="0.001 0.001 0.001" />
        <mesh name="palm" file="mesh/palm.stl" scale="0.001 0.001 0.001" />
        <mesh name="index_meta" file="mesh/index_meta.stl" scale="0.001 0.001 0.001" />
        <mesh name="middle_meta" file="mesh/middle_meta.stl" scale="0.001 0.001 0.001" />
        <mesh name="ring_meta" file="mesh/ring_meta.stl" scale="0.001 0.001 0.001" />
        <mesh name="pinky_meta" file="mesh/pinky_meta.stl" scale="0.001 0.001 0.001" />

        <mesh name="thumb_base" file="mesh/thumb_base.stl" scale="0.001 0.001 0.001" />
        <mesh name="thumb_pp" file="mesh/thumb_pp.stl" scale="0.001 0.001 0.001" />
        <mesh name="thumb_mp" file="mesh/thumb_mp.stl" scale="0.001 0.001 0.001" />
        <mesh name="thumb_dp" file="mesh/thumb_dp.stl" scale="0.001 0.001 0.001" />

        <mesh name="index_pp" file="mesh/index_pp.stl" scale="0.001 0.001 0.001" />
        <mesh name="index_mp" file="mesh/index_mp.stl" scale="0.001 0.001 0.001" />
        <mesh name="index_dp" file="mesh/index_dp.stl" scale="0.001 0.001 0.001" />

        <mesh name="middle_pp" file="mesh/middle_pp.stl" scale="0.001 0.001 0.001" />
        <mesh name="middle_mp" file="mesh/middle_mp.stl" scale="0.001 0.001 0.001" />
        <mesh name="middle_dp" file="mesh/middle_dp.stl" scale="0.001 0.001 0.001" />

        <mesh name="ring_pp" file="mesh/ring_pp.stl" scale="0.001 0.001 0.001" />
        <mesh name="ring_mp" file="mesh/ring_mp.stl" scale="0.001 0.001 0.001" />
        <mesh name="ring_dp" file="mesh/ring_dp.stl" scale="0.001 0.001 0.001" />

        <mesh name="pinky_pp" file="mesh/pinky_pp.stl" scale="0.001 0.001 0.001" />
        <mesh name="pinky_mp" file="mesh/pinky_mp.stl" scale="0.001 0.001 0.001" />
        <mesh name="pinky_dp" file="mesh/pinky_dp.stl" scale="0.001 0.001 0.001" />
    </asset>
    <contact>
        
        <exclude body1="palm" body2="thumb_base" />
        <exclude body1="thumb_base" body2="thumb_pp" />
        <exclude body1="palm" body2="thumb_pp" />  
        <exclude body1="thumb_pp" body2="thumb_mp" />
        <exclude body1="thumb_mp" body2="thumb_dp" />

        <exclude body1="palm" body2="index_pp" />
        <exclude body1="index_pp" body2="index_mp" />
        <exclude body1="index_mp" body2="index_dp" />
        
        
        <exclude body1="palm" body2="middle_pp" />
        <exclude body1="middle_pp" body2="middle_mp" />
        <exclude body1="middle_mp" body2="middle_dp" />

        <exclude body1="palm" body2="ring_pp" />
        <exclude body1="ring_pp" body2="ring_mp" />
        <exclude body1="ring_mp" body2="ring_dp" />

        <exclude body1="palm" body2="pinky_pp" />
        <exclude body1="pinky_pp" body2="pinky_mp" />
        <exclude body1="pinky_mp" body2="pinky_dp" />
    </contact>

    <sensor>
        <jointpos name="root2thumb_base" joint="root2thumb_base" />
        <jointpos name="thumb_base2pp" joint="thumb_base2pp" />
        <jointpos name="thumb_pp2mp" joint="thumb_pp2mp" />
        <jointpos name="thumb_mp2dp" joint="thumb_mp2dp" />

        <jointpos name="root2index_pp" joint="root2index_pp" />
        <jointpos name="index_pp2mp" joint="index_pp2mp" />
        <jointpos name="index_mp2dp" joint="index_mp2dp" />

        <jointpos name="root2middle_pp" joint="root2middle_pp" />
        <jointpos name="middle_pp2mp" joint="middle_pp2mp" />
        <jointpos name="middle_mp2dp" joint="middle_mp2dp" />

        <jointpos name="root2ring_pp" joint="root2ring_pp" />
        <jointpos name="ring_pp2mp" joint="ring_pp2mp" />
        <jointpos name="ring_mp2dp" joint="ring_mp2dp" />

        <jointpos name="root2pinky_pp" joint="root2pinky_pp" />
        <jointpos name="pinky_pp2mp" joint="pinky_pp2mp" />
        <jointpos name="pinky_mp2dp" joint="pinky_mp2dp" />
    </sensor>
    
    <actuator>
        
        <position name="root2thumb_base" joint="root2thumb_base" ctrlrange="0 2.27" kp="1" />
        <position name="thumb_base2pp" joint="thumb_base2pp" ctrlrange="-1.66 1.05" kp="1" />
        <position name="thumb_pp2mp" joint="thumb_pp2mp" ctrlrange="0 0.96" kp="4" />

        <position name="root2index_pp" joint="root2index_pp" ctrlrange="0 0.83" />
        <position name="index_pp2mp" joint="index_pp2mp" ctrlrange="0 0.96" kp="4" />

        <position name="root2middle_pp" joint="root2middle_pp" ctrlrange="0 0.83" />
        <position name="middle_pp2mp" joint="middle_pp2mp" ctrlrange="0 0.96" kp="4" />

        <position name="root2ring_pp" joint="root2ring_pp" ctrlrange="0 0.83" />
        <position name="ring_pp2mp" joint="ring_pp2mp" ctrlrange="0 0.96" kp="4" />

        <position name="root2pinky_pp" joint="root2pinky_pp" ctrlrange="0 0.83" />
        <position name="pinky_pp2mp" joint="pinky_pp2mp" ctrlrange="0 0.96" kp="4" />
    </actuator>

    
    
    <tendon>
        
        <fixed name="thumb_pp2mp">
            <joint joint="thumb_pp2mp_virt" coef="1" />
            <joint joint="thumb_pp2mp" coef="-1" />
        </fixed>
        <fixed name="thumb_jointlink">
            <joint joint="thumb_pp2mp" coef="0.71" />
            <joint joint="thumb_mp2dp_virt" coef="-1" />
        </fixed>
        <fixed name="thumb_mp2dp">
            <joint joint="thumb_mp2dp_virt" coef="1" />
            <joint joint="thumb_mp2dp" coef="-1" />
        </fixed>

        
        <fixed name="root2index_pp">
            <joint joint="root2index_pp_virt" coef="1" />
            <joint joint="root2index_pp" coef="-1" />
        </fixed>
        <fixed name="index_pp2mp">
            <joint joint="index_pp2mp_virt" coef="1" />
            <joint joint="index_pp2mp" coef="-1" />
        </fixed>
        <fixed name="index_jointlink">
            <joint joint="index_pp2mp" coef="0.71" />
            <joint joint="index_mp2dp_virt" coef="-1" />
        </fixed>
        <fixed name="index_mp2dp">
            <joint joint="index_mp2dp_virt" coef="1" />
            <joint joint="index_mp2dp" coef="-1" />
        </fixed>

        
        <fixed name="root2middle_pp">
            <joint joint="root2middle_pp_virt" coef="1" />
            <joint joint="root2middle_pp" coef="-1" />
        </fixed>
        <fixed name="middle_pp2mp">
            <joint joint="middle_pp2mp_virt" coef="1" />
            <joint joint="middle_pp2mp" coef="-1" />
        </fixed>
        <fixed name="middle_jointlink">
            <joint joint="middle_pp2mp" coef="0.71" />
            <joint joint="middle_mp2dp_virt" coef="-1" />
        </fixed>
        <fixed name="middle_mp2dp">
            <joint joint="middle_mp2dp_virt" coef="1" />
            <joint joint="middle_mp2dp" coef="-1" />
        </fixed>

        
        <fixed name="root2ring_pp">
            <joint joint="root2ring_pp_virt" coef="1" />
            <joint joint="root2ring_pp" coef="-1" />
        </fixed>
        <fixed name="ring_pp2mp">
            <joint joint="ring_pp2mp_virt" coef="1" />
            <joint joint="ring_pp2mp" coef="-1" />
        </fixed>
        <fixed name="ring_jointlink">
            <joint joint="ring_pp2mp" coef="0.71" />
            <joint joint="ring_mp2dp_virt" coef="-1" />
        </fixed>
        <fixed name="ring_mp2dp">
            <joint joint="ring_mp2dp_virt" coef="1" />
            <joint joint="ring_mp2dp" coef="-1" />
        </fixed>

        
        <fixed name="root2pinky_pp">
            <joint joint="root2pinky_pp_virt" coef="1" />
            <joint joint="root2pinky_pp" coef="-1" />
        </fixed>
        <fixed name="pinky_pp2mp">
            <joint joint="pinky_pp2mp_virt" coef="1" />
            <joint joint="pinky_pp2mp" coef="-1" />
        </fixed>
        <fixed name="pinky_jointlink">
            <joint joint="pinky_pp2mp" coef="0.71" />
            <joint joint="pinky_mp2dp_virt" coef="-1" />
        </fixed>
        <fixed name="pinky_mp2dp">
            <joint joint="pinky_mp2dp_virt" coef="1" />
            <joint joint="pinky_mp2dp" coef="-1" />
        </fixed>
    </tendon>
<worldbody>
        <body name="root">
        
        <geom mesh="base" rgba="0.2 0.2 0.2 1" />
        <body name="palm">
            
            <geom mesh="palm" />
            <geom mesh="index_meta" />
            <geom mesh="middle_meta" />
            <geom mesh="ring_meta" />
            <geom mesh="pinky_meta" />
            
            <body name="thumb_base">
                <joint name="root2thumb_base" axis="0.297249628842018  -0.700414486434294  -0.648893061564281" pos="-0.029450000000000   0.061590000000000  -0.006270000000000" range="0 2.27" />
                <geom mesh="thumb_base" />
                <body name="thumb_pp">
                    <joint name="thumb_base2pp" axis="-0.088245944430897  -0.696856079647288   0.711761376832230" pos="-0.043710695813146   0.059275370639474  -0.010304234233199" range="-1.66 1.05" />
                    <geom mesh="thumb_pp" />
                    <body name="thumb_mp_virt">
                        <joint name="thumb_pp2mp_virt" axis="0.284429826078874  -0.088618171481011  -0.954592318070968" pos="-0.078908   0.047288  -0.017923" range="0 0.96" />
                        <inertial pos="0 0 0" mass="0.001" diaginertia="4E-10 4E-10 3E-10" />
                        <body name="thumb_mp">
                            <joint name="thumb_pp2mp" axis="0.284429826078874  -0.088618171481011  -0.954592318070968" pos="-0.090266   0.045142  -0.021148" range="0 0.96" />
                            <geom mesh="thumb_mp" />
                            <body name="thumb_dp_virt">
                                <joint name="thumb_mp2dp_virt" axis="0.284429826078874  -0.088618171481011  -0.954592318070968" pos="-0.115347   0.040404  -0.028269" range="0 0.68" />
                                <inertial pos="0 0 0" mass="0.001" diaginertia="4E-10 4E-10 3E-10" />
                                <body name="thumb_dp">
                                    <joint name="thumb_mp2dp" axis="0.284429826078874  -0.088618171481011  -0.954592318070968" pos="-0.123866   0.038794  -0.030687" range="0 0.68" />
                                    <geom mesh="thumb_dp" />
                                    <body name="thumb_fingertip" pos="-0.13585 0.0392 -0.0347" euler="4.7 -0.25 2.92">
                                    </body>
                                </body>
                            </body>
                        </body>
                    </body>
                </body>
            </body>

            <body name="index_pp_virt">
                <joint name="root2index_pp_virt" axis="-0.990425994580321  -0.104241812967506  -0.090498583905110" pos="-0.029320000000000   0.115440000000000   0.017930000000000" range="0 0.83" />
                <inertial pos="0 0 0" mass="0.001" diaginertia="4E-10 4E-10 3E-10" />
                <body name="index_pp">
                    <joint name="root2index_pp" axis="-0.990425994580321  -0.104241812967506  -0.090498583905110" pos="-0.031385146447244   0.133190847457549   0.020084665795489" range="0 0.83" />
                    <geom mesh="index_pp" />
                    <body name="index_mp_virt">
                        <joint name="index_pp2mp_virt" axis="-0.990425994580321  -0.104241812967506  -0.090498583905110" pos="-0.034941787550830   0.163761751412218   0.023795479109943" range="0 0.96" />
                        <inertial pos="0 0 0" mass="0.001" diaginertia="4E-10 4E-10 3E-10" />
                        <body name="index_mp">
                            <joint name="index_pp2mp" axis="-0.990425994580321  -0.104241812967506  -0.090498583905110" pos="-0.036318551848992   0.175595649717251   0.025231922973603" range="0 0.96" />
                            <geom mesh="index_mp" />
                            <body name="index_dp_virt">
                                <joint name="index_mp2dp_virt" axis="-0.990425994580321  -0.104241812967506  -0.090498583905110" pos="-0.039014715266226   0.198770367231273   0.028044958873269" range="0 0.68" />
                                <inertial pos="0 0 0" mass="0.001" diaginertia="4E-10 4E-10 3E-10" />
                                <body name="index_dp">
                                    <joint name="index_mp2dp" axis="-0.990425994580321  -0.104241812967506  -0.090498583905110" pos="-0.040047288489848   0.207645790960048   0.029122291771014" range="0 0.68" />
                                    <geom mesh="index_dp" />
                                    <body name="index_fingertip" pos="-0.0402 0.2175 0.0261" euler="-2.9 0.11 -1.66">
                                    </body>
                                </body>
                            </body>
                        </body>
                    </body>
                </body>
            </body>

            <body name="middle_pp_virt">
                <joint name="root2middle_pp_virt" axis="-1     0     0" pos="-0.005500000000000   0.117620000000000   0.019690000000000" range="0 0.83" />
                <inertial pos="0 0 0" mass="0.001" diaginertia="4E-10 4E-10 3E-10" />
                <body name="middle_pp">
                    <joint name="root2middle_pp" axis="-1     0     0" pos="-0.005500000000000   0.135485830729544   0.021883648181293" range="0 0.83" />
                    <geom mesh="middle_pp" />
                    <body name="middle_mp_virt">
                        <joint name="middle_pp2mp_virt" axis="-1     0     0" pos="-0.005500000000000   0.170224946036990   0.026149075200473" range="0 0.96" />
                        <inertial pos="0 0 0" mass="0.001" diaginertia="4E-10 4E-10 3E-10" />
                        <body name="middle_mp">
                            <joint name="middle_pp2mp" axis="-1     0     0" pos="-0.005500000000000   0.182135499856686   0.027611507321335" range="0 0.96" />
                            <geom mesh="middle_mp" />
                            <body name="middle_dp_virt">
                                <joint name="middle_mp2dp_virt" axis="-1     0     0" pos="-0.005500000000000   0.207445426723540   0.030719175578166" range="0 0.68" />
                                <inertial pos="0 0 0" mass="0.001" diaginertia="4E-10 4E-10 3E-10" />
                                <body name="middle_dp">
                                    <joint name="middle_mp2dp" axis="-1     0     0" pos="-0.005500000000000   0.216378342088312   0.031815999668812" range="0 0.68" />
                                    <geom mesh="middle_dp" />
                                    <body name="middle_fingertip" pos="-0.0055 0.2251 0.0272" euler="-2.92 0.0 -1.565">
                                    </body>
                                </body>
                            </body>
                        </body>
                    </body>index
                </body>
            </body>

            <body name="ring_pp_virt">
                <joint name="root2ring_pp_virt" axis="-0.990425994580321   0.104241812967506   0.090498583905110" pos="0.018090000000000   0.112480000000000   0.018220000000000" range="0 0.83" />
                <inertial pos="0 0 0" mass="0.001" diaginertia="4E-10 4E-10 3E-10" />
                <body name="ring_pp">
                    <joint name="root2ring_pp" axis="-0.990425994580321   0.104241812967506   0.090498583905110" pos="0.020155146447243   0.130230847457549   0.020374665795489" range="0 0.83" />
                    <geom mesh="ring_pp" />
                    <body name="ring_mp_virt">
                        <joint name="ring_pp2mp_virt" axis="-0.990425994580321   0.104241812967506   0.090498583905110" pos="0.023711787550830   0.160801751412218   0.024085479109943" range="0 0.96" />
                        <inertial pos="0 0 0" mass="0.001" diaginertia="4E-10 4E-10 3E-10" />
                        <body name="ring_mp">
                            <joint name="ring_pp2mp" axis="-0.990425994580321   0.104241812967506   0.090498583905110" pos="0.025088551848992   0.172635649717251   0.025521922973603" range="0 0.96" />
                            <geom mesh="ring_mp" />
                            <body name="ring_dp_virt">
                                <joint name="ring_mp2dp_virt" axis="-0.990425994580321   0.104241812967506   0.090498583905110" pos="0.027784715266226   0.195810367231273   0.028334958873269" range="0 0.68" />
                                <inertial pos="0 0 0" mass="0.001" diaginertia="4E-10 4E-10 3E-10" />
                                <body name="ring_dp">
                                    <joint name="ring_mp2dp" axis="-0.990425994580321   0.104241812967506   0.090498583905110" pos="0.028817288489848   0.204685790960048   0.029412291771014" range="0 0.68" />
                                    <geom mesh="ring_dp" />
                                    <body name="ring_fingertip" pos="0.02695 0.216 0.0244" euler="-2.92 -0.125 -1.425">
                                    </body>
                                </body>
                            </body>
                        </body>
                    </body>
                </body>
            </body>

            <body name="pinky_pp_virt">
                <joint name="root2pinky_pp_virt" axis="-0.950980299137689   0.223061123902897   0.214196651829969" pos="0.041170000000000   0.101870000000000   0.013200000000000" range="0 0.83" />
                <inertial pos="0 0 0" mass="0.001" diaginertia="4E-10 4E-10 3E-10" />
                <body name="pinky_pp">
                    <joint name="root2pinky_pp" axis="-0.950980299137689   0.223061123902897   0.214196651829969" pos="0.045651869374116   0.119205095457698   0.015045890675491" range="0 0.83" />
                    <geom mesh="pinky_pp" />
                    <body name="pinky_mp_virt">
                        <joint name="pinky_pp2mp_virt" axis="-0.950980299137689   0.223061123902897   0.214196651829969" pos="0.052374673435289   0.145207738644245   0.017814726688728" range="0 0.96" />
                        <inertial pos="0 0 0" mass="0.001" diaginertia="4E-10 4E-10 3E-10" />
                        <body name="pinky_mp">
                            <joint name="pinky_pp2mp" axis="-0.950980299137689   0.223061123902897   0.214196651829969" pos="0.055362586351366   0.156764468949377   0.019045320472388" range="0 0.96" />
                            <geom mesh="pinky_mp" />
                            <body name="pinky_dp_virt">
                                <joint name="pinky_mp2dp_virt" axis="-0.950980299137689   0.223061123902897   0.214196651829969" pos="0.060217944839991   0.175544155695216   0.021045035370837" range="0 0.68" />
                                <inertial pos="0 0 0" mass="0.001" diaginertia="4E-10 4E-10 3E-10" />
                                <body name="pinky_dp">
                                    <joint name="pinky_mp2dp" axis="-0.950980299137689   0.223061123902897   0.214196651829969" pos="0.062458879527049   0.184211703424065   0.021967980708582" range="0 0.68" />
                                    <geom mesh="pinky_dp" />
                                    <body name="pinky_fingertip" pos="0.06295 0.1938 0.0186" euler="-2.92 -0.25 -1.3">
                                    </body>
                                </body>
                            </body>
                        </body>
                    </body>
                </body>
            </body>
        </body>
    </body>
    
</worldbody>
</mujoco>